<?xml version="1.0" ?>
<sdf version='1.9'>
  <model name='vehicle_blue' canonical_link='chassis'>
    <link name='chassis'>
      <pose>0.5 0 0.4 0 -0 0</pose>
      <inertial>
        <mass>1.14395</mass>
        <inertia>
          <ixx>0.002</ixx>
          <ixy>0</ixy>
          <ixz>0</ixz>
          <iyy>0.002</iyy>
          <iyz>0</iyz>
          <izz>0.002</izz>
        </inertia>
        <pose>0 0 0 0 -0 0</pose>
      </inertial>
      <visual name='visual'>
        <geometry>
          <box>
            <size>2 1 0.5</size>
          </box>
        </geometry>
        <material>
          <ambient>0 0 1 1</ambient>
          <diffuse>0 0 1 1</diffuse>
          <specular>0 0 1 1</specular>
        </material>
      </visual>
      <collision name='collision'>
        <geometry>
          <box>
            <size>2 1 0.5</size>
          </box>
        </geometry>
        <surface>
          <friction>
            <ode/>
          </friction>
          <bounce/>
          <contact/>
        </surface>
      </collision>
      <sensor name='imu_sensor' type='imu'>
        <always_on>1</always_on>
        <update_rate>1</update_rate>
        <visualize>true</visualize>
        <topic>imu</topic>
      </sensor>
    </link>

    <link name='left_wheel'>
      <pose>0 0.6 0.4 -1.5707 0 0</pose>
      <inertial>
        <mass>1</mass>
        <inertia>
          <ixx>0.0002</ixx>
          <ixy>0</ixy>
          <ixz>0</ixz>
          <iyy>0.0002</iyy>
          <iyz>0</iyz>
          <izz>0.0002</izz>
        </inertia>
        <pose>0 0 0 0 -0 0</pose>
      </inertial>
      <visual name='visual'>
        <geometry>
          <cylinder>
            <radius>0.40000000000000002</radius>
            <length>0.20000000000000001</length>
          </cylinder>
        </geometry>
        <material>
          <ambient>1 0 0 1</ambient>
          <diffuse>1 0 0 1</diffuse>
          <specular>1 0 0 1</specular>
        </material>
      </visual>
      <collision name='collision'>
        <geometry>
          <cylinder>
            <radius>0.40000000000000002</radius>
            <length>0.20000000000000001</length>
          </cylinder>
        </geometry>
        <surface>
          <friction>
            <ode/>
          </friction>
          <bounce/>
          <contact/>
        </surface>
      </collision>
      <enable_wind>false</enable_wind>
    </link>
    <link name='right_wheel'>
      <pose>0 -0.6 0.4 -1.5707 0 0</pose>
      <inertial>
        <mass>1</mass>
        <inertia>
          <ixx>0.0002</ixx>
          <ixy>0</ixy>
          <ixz>0</ixz>
          <iyy>0.0002</iyy>
          <iyz>0</iyz>
          <izz>0.0002</izz>
        </inertia>
        <pose>0 0 0 0 -0 0</pose>
      </inertial>
      <visual name='visual'>
        <geometry>
          <cylinder>
            <radius>0.40000000000000002</radius>
            <length>0.20000000000000001</length>
          </cylinder>
        </geometry>
        <material>
          <ambient>1 0 0 1</ambient>
          <diffuse>1 0 0 1</diffuse>
          <specular>1 0 0 1</specular>
        </material>
      </visual>
      <collision name='collision'>
        <geometry>
          <cylinder>
            <radius>0.40000000000000002</radius>
            <length>0.20000000000000001</length>
          </cylinder>
        </geometry>
        <surface>
          <friction>
            <ode/>
          </friction>
          <bounce/>
          <contact/>
        </surface>
      </collision>
      <enable_wind>false</enable_wind>
    </link>

    <frame name='caster_frame' attached_to='chassis'>
      <pose>0.8 0 -0.2 0 0 0</pose>
    </frame>
    <link name='caster'>
      <pose relative_to='caster_frame'/>
      <inertial>
        <mass>1</mass>
        <inertia>
          <ixx>0.0002</ixx>
          <ixy>0</ixy>
          <ixz>0</ixz>
          <iyy>0.0002</iyy>
          <iyz>0</iyz>
          <izz>0.0002</izz>
        </inertia>
        <pose>0 0 0 0 -0 0</pose>
      </inertial>
      <visual name='visual'>
        <geometry>
          <sphere>
            <radius>0.20000000000000001</radius>
          </sphere>
        </geometry>
        <material>
          <ambient>0 1 0 1</ambient>
          <diffuse>0 1 0 1</diffuse>
          <specular>0 1 0 1</specular>
        </material>
      </visual>
      <collision name='collision'>
        <geometry>
          <sphere>
            <radius>0.20000000000000001</radius>
          </sphere>
        </geometry>
        <surface>
          <friction>
            <ode/>
          </friction>
          <bounce/>
          <contact/>
        </surface>
      </collision>
      <enable_wind>false</enable_wind>
    </link>

    <joint name='left_wheel_joint' type='revolute'>
      <pose>0 0 0 0 -0 0</pose>
      <parent>chassis</parent>
      <child>left_wheel</child>
      <axis>
        <xyz>0 9.6e-05 1</xyz>
        <limit>
          <lower>-1.7976900000000001e+308</lower>
          <upper>1.7976900000000001e+308</upper>
          <effort>inf</effort>
          <velocity>inf</velocity>
          <stiffness>100000000</stiffness>
          <dissipation>1</dissipation>
        </limit>
        <dynamics>
          <spring_reference>0</spring_reference>
          <spring_stiffness>0</spring_stiffness>
          <damping>0</damping>
          <friction>0</friction>
        </dynamics>
      </axis>
    </joint>
    <joint name='right_wheel_joint' type='revolute'>
      <pose>0 0 0 0 -0 0</pose>
      <parent>chassis</parent>
      <child>right_wheel</child>
      <axis>
        <xyz>0 9.6e-05 1</xyz>
        <limit>
          <lower>-1.7976900000000001e+308</lower>
          <upper>1.7976900000000001e+308</upper>
          <effort>inf</effort>
          <velocity>inf</velocity>
          <stiffness>100000000</stiffness>
          <dissipation>1</dissipation>
        </limit>
        <dynamics>
          <spring_reference>0</spring_reference>
          <spring_stiffness>0</spring_stiffness>
          <damping>0</damping>
          <friction>0</friction>
        </dynamics>
      </axis>
    </joint>
    <joint name='caster_wheel' type='ball'>
      <parent>chassis</parent>
      <child>caster</child>
      <xyz>0 0 0</xyz>
    </joint>

      <!-- lidar sensor -->
    <frame name="lidar_frame" attached_to='chassis'>
      <pose>0.8 0 0.2 0 0 0</pose>
    </frame>
    <link name="lidar_link">
      <pose relative_to='lidar_frame'/>
      <inertial>
        <mass>0.1</mass>
        <inertia>
          <ixx>0.0000000000000000000000002</ixx>
          <iyy>0.0000000000000000000000002</iyy>
          <izz>0.0000000000000000000000002</izz>
        </inertia>
      </inertial>
      <collision name="collision">
        <geometry>
          <box>
            <size>0.1 0.1 0.1</size>
          </box>
        </geometry>
      </collision>
      <visual name="visual">
        <geometry>
          <box>
            <size>0.1 0.1 0.1</size>
          </box>
        </geometry>
      </visual>
      <sensor name='gpu_lidar' type='gpu_lidar'>
        <pose>0 0 0 0 0 0</pose>
        <topic>scan</topic>
        <ignition_frame_id>vehicle_blue/lidar_link</ignition_frame_id>
        <update_rate>500</update_rate>
        <lidar>
          <scan>
            <horizontal>
              <samples>640</samples>
              <resolution>1</resolution>
              <min_angle>-3.14159265359</min_angle>
              <max_angle>3.14159265359</max_angle>
            </horizontal>
            <vertical>
              <samples>1</samples>
              <resolution>1</resolution>
              <min_angle>0.0</min_angle>
              <max_angle>0.0</max_angle>
            </vertical>
          </scan>
          <range>
            <min>0.08</min>
            <max>10.0</max>
            <resolution>0.01</resolution>
          </range>
        </lidar>
        <visualize>true</visualize>
      </sensor>
    </link>

    <joint name='lidar_joint' type='fixed'>
      <parent>chassis</parent>
      <child>lidar_link</child>
      <xyz>0 0 0</xyz>
    </joint>

    <plugin
          filename="libignition-gazebo-diff-drive-system.so"
          name="ignition::gazebo::systems::DiffDrive">
          <left_joint>left_wheel_joint</left_joint>
          <right_joint>right_wheel_joint</right_joint>
          <wheel_separation>1.2</wheel_separation>
          <wheel_radius>0.4</wheel_radius>
          <odom_publish_frequency>1</odom_publish_frequency>
      </plugin>

      <!-- control plugin -->

      <plugin filename="libignition-gazebo-triggered-publisher-system.so"
        name="ignition::gazebo::systems::TriggeredPublisher">
        <input type="ignition.msgs.Int32" topic="/keyboard/keypress">
            <match field="data">16777235</match>
        </input>
        <output type="ignition.msgs.Twist" topic="/model/vehicle_blue/cmd_vel">
            linear: {x: 2}, angular: {z: 0.0}
        </output>
      </plugin>
      <plugin filename="libignition-gazebo-triggered-publisher-system.so"
        name="ignition::gazebo::systems::TriggeredPublisher">
        <input type="ignition.msgs.Int32" topic="/keyboard/keypress">
            <match field="data">16777234</match>
        </input>
        <output type="ignition.msgs.Twist" topic="/model/vehicle_blue/cmd_vel">
            linear: {x: 0.0}, angular: {z: 1}
        </output>
      </plugin>
      <plugin filename="libignition-gazebo-triggered-publisher-system.so"
        name="ignition::gazebo::systems::TriggeredPublisher">
        <input type="ignition.msgs.Int32" topic="/keyboard/keypress">
            <match field="data">16777236</match>
        </input>
        <output type="ignition.msgs.Twist" topic="/model/vehicle_blue/cmd_vel">
            linear: {x: 0.0}, angular: {z: -1}
        </output>
      </plugin>
      <plugin filename="libignition-gazebo-triggered-publisher-system.so"
        name="ignition::gazebo::systems::TriggeredPublisher">
        <input type="ignition.msgs.Int32" topic="/keyboard/keypress">
            <match field="data">16777237</match>
        </input>
        <output type="ignition.msgs.Twist" topic="/model/vehicle_blue/cmd_vel">
            linear: {x: -2}, angular: {z: 0.0}
        </output>
      </plugin>
      <plugin filename="libignition-gazebo-triggered-publisher-system.so"
        name="ignition::gazebo::systems::TriggeredPublisher">
        <input type="ignition.msgs.Int32" topic="/keyboard/keypress">
            <match field="data">65</match>
        </input>
        <output type="ignition.msgs.Twist" topic="/model/vehicle_blue/cmd_vel">
            linear: {x: 0.0}, angular: {z: 0.0}
        </output>
      </plugin>
      <plugin
        filename="ignition-gazebo-joint-state-publisher-system"
        name="ignition::gazebo::systems::JointStatePublisher">
      </plugin>

      <plugin
        filename="ignition-gazebo-pose-publisher-system"
        name="ignition::gazebo::systems::PosePublisher">
        <publish_link_pose>true</publish_link_pose>
        <use_pose_vector_msg>true</use_pose_vector_msg>
        <static_publisher>true</static_publisher>
        <static_update_frequency>1</static_update_frequency>
      </plugin>

      <plugin
        filename="ignition-gazebo-odometry-publisher-system"
        name="ignition::gazebo::systems::OdometryPublisher">
        <odom_frame>vehicle_blue/odom</odom_frame>
        <robot_base_frame>vehicle_blue</robot_base_frame>
      </plugin>

  </model>
</sdf>
